<?xml version="1.0" ?>
<robot name="robot" xmlns:xacro="http://www.ros.org/wiki/xacro">

<xacro:include filename="$(find robot_description)/urdf/materials.xacro" />
<xacro:include filename="$(find robot_description)/urdf/robot.trans" />
<xacro:include filename="$(find robot_description)/urdf/robot.gazebo" />

<!-- 2450g chassis weight -->
<!-- 136g wheel weight -->

<link name="base_link">
  <inertial>
    <origin xyz="-0.003275137237927211 -0.002823580614262791 0.059956452659400854" rpy="0 0 0"/>
    <mass value="1.5244260650988377"/>
    <inertia ixx="0.022302" iyy="0.004208" izz="0.023534" ixy="0.0" iyz="-0.0" ixz="0.0"/>
  </inertial>
  <visual>
    <origin xyz="0 0 0" rpy="0 0 0"/>
    <geometry>
      <mesh filename="package://robot_description/meshes/base_link.stl" scale="0.001 0.001 0.001"/>
    </geometry>
    <material name="silver"/>
  </visual>
  <collision>
    <origin xyz="0 0 0" rpy="0 0 0"/>
    <geometry>
      <mesh filename="package://robot_description/meshes/base_link.stl" scale="0.001 0.001 0.001"/>
    </geometry>
  </collision>
</link>

<link name="right_rear_wheel_1">
  <inertial>
    <origin xyz="-0.020998330716552938 4.193857151557623e-07 6.892554227713732e-08" rpy="0 0 0"/>
    <mass value="0.3231421029960238"/>
    <inertia ixx="0.00032" iyy="0.000208" izz="0.000208" ixy="0.0" iyz="-0.0" ixz="-0.0"/>
  </inertial>
  <visual>
    <origin xyz="0.093275 -0.142176 -0.01802" rpy="0 0 0"/>
    <geometry>
      <mesh filename="package://robot_description/meshes/right_rear_wheel_1.stl" scale="0.001 0.001 0.001"/>
    </geometry>
    <material name="silver"/>
  </visual>
  <collision>
    <origin xyz="0.093275 -0.142176 -0.01802" rpy="0 0 0"/>
    <geometry>
      <mesh filename="package://robot_description/meshes/right_rear_wheel_1.stl" scale="0.001 0.001 0.001"/>
    </geometry>
  </collision>
</link>

<link name="left_rear_wheel_1">
  <inertial>
    <origin xyz="0.020998056240739887 4.193857091050468e-07 6.892558756382838e-08" rpy="0 0 0"/>
    <mass value="0.32314210299575874"/>
    <inertia ixx="0.00032" iyy="0.000208" izz="0.000208" ixy="-0.0" iyz="-0.0" ixz="0.0"/>
  </inertial>
  <visual>
    <origin xyz="-0.086725 -0.142176 -0.01802" rpy="0 0 0"/>
    <geometry>
      <mesh filename="package://robot_description/meshes/left_rear_wheel_1.stl" scale="0.001 0.001 0.001"/>
    </geometry>
    <material name="silver"/>
  </visual>
  <collision>
    <origin xyz="-0.086725 -0.142176 -0.01802" rpy="0 0 0"/>
    <geometry>
      <mesh filename="package://robot_description/meshes/left_rear_wheel_1.stl" scale="0.001 0.001 0.001"/>
    </geometry>
  </collision>
</link>

<link name="left_front_wheel_1">
  <inertial>
    <origin xyz="0.021001669283437538 4.193857211787222e-07 6.892558681442784e-08" rpy="0 0 0"/>
    <mass value="0.32314210299575896"/>
    <inertia ixx="0.00032" iyy="0.000208" izz="0.000208" ixy="0.0" iyz="-0.0" ixz="-0.0"/>
  </inertial>
  <visual>
    <origin xyz="-0.086725 0.147824 -0.01802" rpy="0 0 0"/>
    <geometry>
      <mesh filename="package://robot_description/meshes/left_front_wheel_1.stl" scale="0.001 0.001 0.001"/>
    </geometry>
    <material name="silver"/>
  </visual>
  <collision>
    <origin xyz="-0.086725 0.147824 -0.01802" rpy="0 0 0"/>
    <geometry>
      <mesh filename="package://robot_description/meshes/left_front_wheel_1.stl" scale="0.001 0.001 0.001"/>
    </geometry>
  </collision>
</link>

<link name="right_front_wheel_1">
  <inertial>
    <origin xyz="-0.02100194375925407 4.1938572134525565e-07 6.892558681789729e-08" rpy="0 0 0"/>
    <mass value="0.3231421029957589"/>
    <inertia ixx="0.00032" iyy="0.000208" izz="0.000208" ixy="-0.0" iyz="-0.0" ixz="0.0"/>
  </inertial>
  <visual>
    <origin xyz="0.093275 0.147824 -0.01802" rpy="0 0 0"/>
    <geometry>
      <mesh filename="package://robot_description/meshes/right_front_wheel_1.stl" scale="0.001 0.001 0.001"/>
    </geometry>
    <material name="silver"/>
  </visual>
  <collision>
    <origin xyz="0.093275 0.147824 -0.01802" rpy="0 0 0"/>
    <geometry>
      <mesh filename="package://robot_description/meshes/right_front_wheel_1.stl" scale="0.001 0.001 0.001"/>
    </geometry>
  </collision>
</link>

<joint name="Rev5" type="continuous">
  <origin xyz="-0.093275 0.142176 0.01802" rpy="0 0 0"/>
  <parent link="base_link"/>
  <child link="right_rear_wheel_1"/>
  <axis xyz="1.0 0.0 0.0"/>
</joint>

<joint name="Rev6" type="continuous">
  <origin xyz="0.086725 0.142176 0.01802" rpy="0 0 0"/>
  <parent link="base_link"/>
  <child link="left_rear_wheel_1"/>
  <axis xyz="1.0 0.0 0.0"/>
</joint>

<joint name="Rev7" type="continuous">
  <origin xyz="0.086725 -0.147824 0.01802" rpy="0 0 0"/>
  <parent link="base_link"/>
  <child link="left_front_wheel_1"/>
  <axis xyz="1.0 0.0 0.0"/>
</joint>

<joint name="Rev8" type="continuous">
  <origin xyz="-0.093275 -0.147824 0.01802" rpy="0 0 0"/>
  <parent link="base_link"/>
  <child link="right_front_wheel_1"/>
  <axis xyz="1.0 0.0 0.0"/>
</joint>

</robot>
