<?xml version="1.0"?>
<!-- =================================================================================== -->
<!-- |    This document was autogenerated by xacro from /home/helios/examplo-ros2/install/robot_description/share/robot_description/urdf/robots/examplo.urdf.xacro | -->
<!-- |    EDITING THIS FILE BY HAND IS NOT RECOMMENDED                                 | -->
<!-- =================================================================================== -->
<robot name="examplo">
  <!-- Specify some standard inertial calculations https://en.wikipedia.org/wiki/List_of_moments_of_inertia -->
  <!-- These make use of xacro's mathematical functionality -->
  <material name="black">
    <color rgba="0.0 0.0 0.0 1.0" />
  </material>
  <material name="blue">
    <color rgba="0.13725490196078433 0.43137254901960786 0.5882352941176471 1.0" />
  </material>
  <material name="green">
    <color rgba="0.0 0.8 0.0 1.0" />
  </material>
  <material name="grey">
    <color rgba="0.2 0.2 0.2 1.0" />
  </material>
  <material name="yellow">
    <color rgba="1.0 0.8431372549019608 0.0 1" />
  </material>
  <material name="orange">
    <color rgba="0.9529411764705882 0.5294117647058824 0.1843137254901961 1" />
  </material>
  <material name="brown">
    <color rgba="0.8705882352941177 0.8117647058823529 0.7647058823529411 1.0" />
  </material>
  <material name="red">
    <color rgba="0.8 0.0 0.0 1.0" />
  </material>
  <material name="white">
    <color rgba="1.0 1.0 1.0 1.0" />
  </material>
  <material name="silver">
    <color rgba="0.700 0.700 0.700 1.000" />
  </material>
  <ros2_control name="examplo" type="system">
    <hardware>
      <plugin>robot_hardware/IsaacDriveHardware</plugin>
      <param name="example_param_hw_start_duration_sec">3.0</param>
      <param name="example_param_hw_stop_duration_sec">3.0</param>
    </hardware>
    <joint name="front_right_mecanum_joint">
      <command_interface name="velocity">
        <param name="min">-1</param>
        <param name="max">1</param>
      </command_interface>
      <state_interface name="position" />
      <state_interface name="velocity" />
    </joint>
    <joint name="rear_left_mecanum_joint">
      <command_interface name="velocity">
        <param name="min">-1</param>
        <param name="max">1</param>
      </command_interface>
      <state_interface name="position" />
      <state_interface name="velocity" />
    </joint>
    <joint name="front_left_mecanum_joint">
      <command_interface name="velocity">
        <param name="min">-1</param>
        <param name="max">1</param>
      </command_interface>
      <state_interface name="position" />
      <state_interface name="velocity" />
    </joint>
    <joint name="rear_right_mecanum_joint">
      <command_interface name="velocity">
        <param name="min">-1</param>
        <param name="max">1</param>
      </command_interface>
      <state_interface name="position" />
      <state_interface name="velocity" />
    </joint>
  </ros2_control>
  <link name="base_link" />
  <link name="chassis_link">
    <inertial>
      <origin rpy="0 0 0" xyz="0 0 -0.0675" />
      <mass value="2.45" />
      <inertia ixx="0.025954687500000004" ixy="0.0" ixz="0.0" iyy="0.0103359375" iyz="0.0" izz="0.028848750000000003" />
    </inertial>
    <visual>
      <origin rpy="0 0 0" xyz="0 0 0" />
      <geometry>
        <mesh filename="package://robot_description/meshes/chassis.stl" scale="0.001 0.001 0.001" />
      </geometry>
      <material name="blue" />
    </visual>
    <collision>
      <origin rpy="0 0 0" xyz="0 0 -0.0675" />
      <geometry>
        <box size="0.18 0.33 0.135" />
      </geometry>
    </collision>
  </link>
  <gazebo reference="chassis">
    <material>Gazebo/Blue</material>
  </gazebo>
  <joint name="chassis_joint" type="fixed">
    <parent link="base_link" />
    <child link="chassis_link" />
    <origin xyz="0 0 0" />
  </joint>
  <link name="front_right_mecanum_link">
    <inertial>
      <origin rpy="0 1.5707963267948966 0" xyz="0 0 0" />
      <mass value="0.136" />
      <inertia ixx="7.117696e-05" ixy="0.0" ixz="0.0" iyy="7.117696e-05" iyz="0.0" izz="0.00010236992" />
    </inertial>
    <visual>
      <origin rpy="0 0 0" xyz="0 0 0" />
      <geometry>
        <mesh filename="package://robot_description/meshes/mec_hub_1.stl" scale="0.001 0.001 0.001" />
      </geometry>
      <material name="orange" />
    </visual>
    <collision>
      <origin rpy="0 0 0" xyz="0 0 0" />
      <geometry>
        <cylinder length="0.042" radius="0.0388" />
      </geometry>
    </collision>
  </link>
  <joint name="front_right_mecanum_joint" type="continuous">
    <origin rpy="0 1.5707963267948966 0" xyz="0.108 0.145 -0.121" />
    <parent link="chassis_link" />
    <child link="front_right_mecanum_link" />
    <axis xyz="0.0 0.0 -1.0" />
  </joint>
  <link name="front_right_roller_0">
    <visual>
      <origin rpy="0 0 0" xyz="0 0 0" />
      <geometry>
        <mesh filename="package://robot_description/meshes/roller.stl" scale="0.001 0.001 0.001" />
      </geometry>
      <material name="grey" />
    </visual>
    <collision>
      <origin rpy="0 0 0" xyz="0 0 0" />
      <geometry>
        <sphere radius="0.0097" />
      </geometry>
    </collision>
    <collision>
      <origin rpy="0 0 0" xyz="0 0 0.00792" />
      <geometry>
        <sphere radius="0.00952" />
      </geometry>
    </collision>
    <collision>
      <origin rpy="0 0 0" xyz="0 0 -0.00792" />
      <geometry>
        <sphere radius="0.00952" />
      </geometry>
    </collision>
    <collision>
      <origin rpy="0 0 0" xyz="0 0 0.01584" />
      <geometry>
        <sphere radius="0.008985" />
      </geometry>
    </collision>
    <collision>
      <origin rpy="0 0 0" xyz="0 0 -0.01584" />
      <geometry>
        <sphere radius="0.008985" />
      </geometry>
    </collision>
  </link>
  <joint name="front_right_roller_0_joint" type="continuous">
    <origin rpy="0.0 0.7853981633974483 0" xyz="0.0 0.0388 0" />
    <parent link="front_right_mecanum_link" />
    <child link="front_right_roller_0" />
    <axis xyz="0.0 0.0 1.0" />
  </joint>
  <link name="front_right_roller_1">
    <visual>
      <origin rpy="0 0 0" xyz="0 0 0" />
      <geometry>
        <mesh filename="package://robot_description/meshes/roller.stl" scale="0.001 0.001 0.001" />
      </geometry>
      <material name="grey" />
    </visual>
    <collision>
      <origin rpy="0 0 0" xyz="0 0 0" />
      <geometry>
        <sphere radius="0.0097" />
      </geometry>
    </collision>
    <collision>
      <origin rpy="0 0 0" xyz="0 0 0.00792" />
      <geometry>
        <sphere radius="0.00952" />
      </geometry>
    </collision>
    <collision>
      <origin rpy="0 0 0" xyz="0 0 -0.00792" />
      <geometry>
        <sphere radius="0.00952" />
      </geometry>
    </collision>
    <collision>
      <origin rpy="0 0 0" xyz="0 0 0.01584" />
      <geometry>
        <sphere radius="0.008985" />
      </geometry>
    </collision>
    <collision>
      <origin rpy="0 0 0" xyz="0 0 -0.01584" />
      <geometry>
        <sphere radius="0.008985" />
      </geometry>
    </collision>
  </link>
  <joint name="front_right_roller_1_joint" type="continuous">
    <origin rpy="0.5048442081024438 0.6016498987064663 0" xyz="0.024940159255837722 0.02972252439301635 0" />
    <parent link="front_right_mecanum_link" />
    <child link="front_right_roller_1" />
    <axis xyz="0.0 0.0 1.0" />
  </joint>
  <link name="front_right_roller_2">
    <visual>
      <origin rpy="0 0 0" xyz="0 0 0" />
      <geometry>
        <mesh filename="package://robot_description/meshes/roller.stl" scale="0.001 0.001 0.001" />
      </geometry>
      <material name="grey" />
    </visual>
    <collision>
      <origin rpy="0 0 0" xyz="0 0 0" />
      <geometry>
        <sphere radius="0.0097" />
      </geometry>
    </collision>
    <collision>
      <origin rpy="0 0 0" xyz="0 0 0.00792" />
      <geometry>
        <sphere radius="0.00952" />
      </geometry>
    </collision>
    <collision>
      <origin rpy="0 0 0" xyz="0 0 -0.00792" />
      <geometry>
        <sphere radius="0.00952" />
      </geometry>
    </collision>
    <collision>
      <origin rpy="0 0 0" xyz="0 0 0.01584" />
      <geometry>
        <sphere radius="0.008985" />
      </geometry>
    </collision>
    <collision>
      <origin rpy="0 0 0" xyz="0 0 -0.01584" />
      <geometry>
        <sphere radius="0.008985" />
      </geometry>
    </collision>
  </link>
  <joint name="front_right_roller_2_joint" type="continuous">
    <origin rpy="0.7734662005153561 0.13638295981692095 0" xyz="0.038210540816873674 0.0067375492934769006 0" />
    <parent link="front_right_mecanum_link" />
    <child link="front_right_roller_2" />
    <axis xyz="0.0 0.0 1.0" />
  </joint>
  <link name="front_right_roller_3">
    <visual>
      <origin rpy="0 0 0" xyz="0 0 0" />
      <geometry>
        <mesh filename="package://robot_description/meshes/roller.stl" scale="0.001 0.001 0.001" />
      </geometry>
      <material name="grey" />
    </visual>
    <collision>
      <origin rpy="0 0 0" xyz="0 0 0" />
      <geometry>
        <sphere radius="0.0097" />
      </geometry>
    </collision>
    <collision>
      <origin rpy="0 0 0" xyz="0 0 0.00792" />
      <geometry>
        <sphere radius="0.00952" />
      </geometry>
    </collision>
    <collision>
      <origin rpy="0 0 0" xyz="0 0 -0.00792" />
      <geometry>
        <sphere radius="0.00952" />
      </geometry>
    </collision>
    <collision>
      <origin rpy="0 0 0" xyz="0 0 0.01584" />
      <geometry>
        <sphere radius="0.008985" />
      </geometry>
    </collision>
    <collision>
      <origin rpy="0 0 0" xyz="0 0 -0.01584" />
      <geometry>
        <sphere radius="0.008985" />
      </geometry>
    </collision>
  </link>
  <joint name="front_right_roller_3_joint" type="continuous">
    <origin rpy="0.6801747615878317 -0.392699081698724 0" xyz="0.03360178566683622 -0.019399999999999994 0" />
    <parent link="front_right_mecanum_link" />
    <child link="front_right_roller_3" />
    <axis xyz="0.0 0.0 1.0" />
  </joint>
  <link name="front_right_roller_4">
    <visual>
      <origin rpy="0 0 0" xyz="0 0 0" />
      <geometry>
        <mesh filename="package://robot_description/meshes/roller.stl" scale="0.001 0.001 0.001" />
      </geometry>
      <material name="grey" />
    </visual>
    <collision>
      <origin rpy="0 0 0" xyz="0 0 0" />
      <geometry>
        <sphere radius="0.0097" />
      </geometry>
    </collision>
    <collision>
      <origin rpy="0 0 0" xyz="0 0 0.00792" />
      <geometry>
        <sphere radius="0.00952" />
      </geometry>
    </collision>
    <collision>
      <origin rpy="0 0 0" xyz="0 0 -0.00792" />
      <geometry>
        <sphere radius="0.00952" />
      </geometry>
    </collision>
    <collision>
      <origin rpy="0 0 0" xyz="0 0 0.01584" />
      <geometry>
        <sphere radius="0.008985" />
      </geometry>
    </collision>
    <collision>
      <origin rpy="0 0 0" xyz="0 0 -0.01584" />
      <geometry>
        <sphere radius="0.008985" />
      </geometry>
    </collision>
  </link>
  <joint name="front_right_roller_4_joint" type="continuous">
    <origin rpy="0.26862199241291235 -0.7380328585233872 0" xyz="0.013270381561035953 -0.03646007368649325 0" />
    <parent link="front_right_mecanum_link" />
    <child link="front_right_roller_4" />
    <axis xyz="0.0 0.0 1.0" />
  </joint>
  <link name="front_right_roller_5">
    <visual>
      <origin rpy="0 0 0" xyz="0 0 0" />
      <geometry>
        <mesh filename="package://robot_description/meshes/roller.stl" scale="0.001 0.001 0.001" />
      </geometry>
      <material name="grey" />
    </visual>
    <collision>
      <origin rpy="0 0 0" xyz="0 0 0" />
      <geometry>
        <sphere radius="0.0097" />
      </geometry>
    </collision>
    <collision>
      <origin rpy="0 0 0" xyz="0 0 0.00792" />
      <geometry>
        <sphere radius="0.00952" />
      </geometry>
    </collision>
    <collision>
      <origin rpy="0 0 0" xyz="0 0 -0.00792" />
      <geometry>
        <sphere radius="0.00952" />
      </geometry>
    </collision>
    <collision>
      <origin rpy="0 0 0" xyz="0 0 0.01584" />
      <geometry>
        <sphere radius="0.008985" />
      </geometry>
    </collision>
    <collision>
      <origin rpy="0 0 0" xyz="0 0 -0.01584" />
      <geometry>
        <sphere radius="0.008985" />
      </geometry>
    </collision>
  </link>
  <joint name="front_right_roller_5_joint" type="continuous">
    <origin rpy="-0.2686219924129122 -0.7380328585233873 0" xyz="-0.013270381561035945 -0.03646007368649325 0" />
    <parent link="front_right_mecanum_link" />
    <child link="front_right_roller_5" />
    <axis xyz="0.0 0.0 1.0" />
  </joint>
  <link name="front_right_roller_6">
    <visual>
      <origin rpy="0 0 0" xyz="0 0 0" />
      <geometry>
        <mesh filename="package://robot_description/meshes/roller.stl" scale="0.001 0.001 0.001" />
      </geometry>
      <material name="grey" />
    </visual>
    <collision>
      <origin rpy="0 0 0" xyz="0 0 0" />
      <geometry>
        <sphere radius="0.0097" />
      </geometry>
    </collision>
    <collision>
      <origin rpy="0 0 0" xyz="0 0 0.00792" />
      <geometry>
        <sphere radius="0.00952" />
      </geometry>
    </collision>
    <collision>
      <origin rpy="0 0 0" xyz="0 0 -0.00792" />
      <geometry>
        <sphere radius="0.00952" />
      </geometry>
    </collision>
    <collision>
      <origin rpy="0 0 0" xyz="0 0 0.01584" />
      <geometry>
        <sphere radius="0.008985" />
      </geometry>
    </collision>
    <collision>
      <origin rpy="0 0 0" xyz="0 0 -0.01584" />
      <geometry>
        <sphere radius="0.008985" />
      </geometry>
    </collision>
  </link>
  <joint name="front_right_roller_6_joint" type="continuous">
    <origin rpy="-0.6801747615878314 -0.3926990816987245 0" xyz="-0.03360178566683621 -0.019400000000000018 0" />
    <parent link="front_right_mecanum_link" />
    <child link="front_right_roller_6" />
    <axis xyz="0.0 0.0 1.0" />
  </joint>
  <link name="front_right_roller_7">
    <visual>
      <origin rpy="0 0 0" xyz="0 0 0" />
      <geometry>
        <mesh filename="package://robot_description/meshes/roller.stl" scale="0.001 0.001 0.001" />
      </geometry>
      <material name="grey" />
    </visual>
    <collision>
      <origin rpy="0 0 0" xyz="0 0 0" />
      <geometry>
        <sphere radius="0.0097" />
      </geometry>
    </collision>
    <collision>
      <origin rpy="0 0 0" xyz="0 0 0.00792" />
      <geometry>
        <sphere radius="0.00952" />
      </geometry>
    </collision>
    <collision>
      <origin rpy="0 0 0" xyz="0 0 -0.00792" />
      <geometry>
        <sphere radius="0.00952" />
      </geometry>
    </collision>
    <collision>
      <origin rpy="0 0 0" xyz="0 0 0.01584" />
      <geometry>
        <sphere radius="0.008985" />
      </geometry>
    </collision>
    <collision>
      <origin rpy="0 0 0" xyz="0 0 -0.01584" />
      <geometry>
        <sphere radius="0.008985" />
      </geometry>
    </collision>
  </link>
  <joint name="front_right_roller_7_joint" type="continuous">
    <origin rpy="-0.7734662005153561 0.13638295981692058 0" xyz="-0.038210540816873674 0.006737549293476883 0" />
    <parent link="front_right_mecanum_link" />
    <child link="front_right_roller_7" />
    <axis xyz="0.0 0.0 1.0" />
  </joint>
  <link name="front_right_roller_8">
    <visual>
      <origin rpy="0 0 0" xyz="0 0 0" />
      <geometry>
        <mesh filename="package://robot_description/meshes/roller.stl" scale="0.001 0.001 0.001" />
      </geometry>
      <material name="grey" />
    </visual>
    <collision>
      <origin rpy="0 0 0" xyz="0 0 0" />
      <geometry>
        <sphere radius="0.0097" />
      </geometry>
    </collision>
    <collision>
      <origin rpy="0 0 0" xyz="0 0 0.00792" />
      <geometry>
        <sphere radius="0.00952" />
      </geometry>
    </collision>
    <collision>
      <origin rpy="0 0 0" xyz="0 0 -0.00792" />
      <geometry>
        <sphere radius="0.00952" />
      </geometry>
    </collision>
    <collision>
      <origin rpy="0 0 0" xyz="0 0 0.01584" />
      <geometry>
        <sphere radius="0.008985" />
      </geometry>
    </collision>
    <collision>
      <origin rpy="0 0 0" xyz="0 0 -0.01584" />
      <geometry>
        <sphere radius="0.008985" />
      </geometry>
    </collision>
  </link>
  <joint name="front_right_roller_8_joint" type="continuous">
    <origin rpy="-0.504844208102444 0.6016498987064662 0" xyz="-0.024940159255837736 0.02972252439301634 0" />
    <parent link="front_right_mecanum_link" />
    <child link="front_right_roller_8" />
    <axis xyz="0.0 0.0 1.0" />
  </joint>
  <link name="rear_left_mecanum_link">
    <inertial>
      <origin rpy="0 1.5707963267948966 0" xyz="0 0 0" />
      <mass value="0.136" />
      <inertia ixx="7.117696e-05" ixy="0.0" ixz="0.0" iyy="7.117696e-05" iyz="0.0" izz="0.00010236992" />
    </inertial>
    <visual>
      <origin rpy="0 0 0" xyz="0 0 0" />
      <geometry>
        <mesh filename="package://robot_description/meshes/mec_hub_1.stl" scale="0.001 0.001 0.001" />
      </geometry>
      <material name="orange" />
    </visual>
    <collision>
      <origin rpy="0 0 0" xyz="0 0 0" />
      <geometry>
        <cylinder length="0.042" radius="0.0388" />
      </geometry>
    </collision>
  </link>
  <joint name="rear_left_mecanum_joint" type="continuous">
    <origin rpy="0 -1.5707963267948966 0" xyz="-0.108 -0.145 -0.121" />
    <parent link="chassis_link" />
    <child link="rear_left_mecanum_link" />
    <axis xyz="0.0 0.0 1.0" />
  </joint>
  <link name="rear_left_roller_0">
    <visual>
      <origin rpy="0 0 0" xyz="0 0 0" />
      <geometry>
        <mesh filename="package://robot_description/meshes/roller.stl" scale="0.001 0.001 0.001" />
      </geometry>
      <material name="grey" />
    </visual>
    <collision>
      <origin rpy="0 0 0" xyz="0 0 0" />
      <geometry>
        <sphere radius="0.0097" />
      </geometry>
    </collision>
    <collision>
      <origin rpy="0 0 0" xyz="0 0 0.00792" />
      <geometry>
        <sphere radius="0.00952" />
      </geometry>
    </collision>
    <collision>
      <origin rpy="0 0 0" xyz="0 0 -0.00792" />
      <geometry>
        <sphere radius="0.00952" />
      </geometry>
    </collision>
    <collision>
      <origin rpy="0 0 0" xyz="0 0 0.01584" />
      <geometry>
        <sphere radius="0.008985" />
      </geometry>
    </collision>
    <collision>
      <origin rpy="0 0 0" xyz="0 0 -0.01584" />
      <geometry>
        <sphere radius="0.008985" />
      </geometry>
    </collision>
  </link>
  <joint name="rear_left_roller_0_joint" type="continuous">
    <origin rpy="0.0 0.7853981633974483 0" xyz="0.0 0.0388 0" />
    <parent link="rear_left_mecanum_link" />
    <child link="rear_left_roller_0" />
    <axis xyz="0.0 0.0 1.0" />
  </joint>
  <link name="rear_left_roller_1">
    <visual>
      <origin rpy="0 0 0" xyz="0 0 0" />
      <geometry>
        <mesh filename="package://robot_description/meshes/roller.stl" scale="0.001 0.001 0.001" />
      </geometry>
      <material name="grey" />
    </visual>
    <collision>
      <origin rpy="0 0 0" xyz="0 0 0" />
      <geometry>
        <sphere radius="0.0097" />
      </geometry>
    </collision>
    <collision>
      <origin rpy="0 0 0" xyz="0 0 0.00792" />
      <geometry>
        <sphere radius="0.00952" />
      </geometry>
    </collision>
    <collision>
      <origin rpy="0 0 0" xyz="0 0 -0.00792" />
      <geometry>
        <sphere radius="0.00952" />
      </geometry>
    </collision>
    <collision>
      <origin rpy="0 0 0" xyz="0 0 0.01584" />
      <geometry>
        <sphere radius="0.008985" />
      </geometry>
    </collision>
    <collision>
      <origin rpy="0 0 0" xyz="0 0 -0.01584" />
      <geometry>
        <sphere radius="0.008985" />
      </geometry>
    </collision>
  </link>
  <joint name="rear_left_roller_1_joint" type="continuous">
    <origin rpy="0.5048442081024438 0.6016498987064663 0" xyz="0.024940159255837722 0.02972252439301635 0" />
    <parent link="rear_left_mecanum_link" />
    <child link="rear_left_roller_1" />
    <axis xyz="0.0 0.0 1.0" />
  </joint>
  <link name="rear_left_roller_2">
    <visual>
      <origin rpy="0 0 0" xyz="0 0 0" />
      <geometry>
        <mesh filename="package://robot_description/meshes/roller.stl" scale="0.001 0.001 0.001" />
      </geometry>
      <material name="grey" />
    </visual>
    <collision>
      <origin rpy="0 0 0" xyz="0 0 0" />
      <geometry>
        <sphere radius="0.0097" />
      </geometry>
    </collision>
    <collision>
      <origin rpy="0 0 0" xyz="0 0 0.00792" />
      <geometry>
        <sphere radius="0.00952" />
      </geometry>
    </collision>
    <collision>
      <origin rpy="0 0 0" xyz="0 0 -0.00792" />
      <geometry>
        <sphere radius="0.00952" />
      </geometry>
    </collision>
    <collision>
      <origin rpy="0 0 0" xyz="0 0 0.01584" />
      <geometry>
        <sphere radius="0.008985" />
      </geometry>
    </collision>
    <collision>
      <origin rpy="0 0 0" xyz="0 0 -0.01584" />
      <geometry>
        <sphere radius="0.008985" />
      </geometry>
    </collision>
  </link>
  <joint name="rear_left_roller_2_joint" type="continuous">
    <origin rpy="0.7734662005153561 0.13638295981692095 0" xyz="0.038210540816873674 0.0067375492934769006 0" />
    <parent link="rear_left_mecanum_link" />
    <child link="rear_left_roller_2" />
    <axis xyz="0.0 0.0 1.0" />
  </joint>
  <link name="rear_left_roller_3">
    <visual>
      <origin rpy="0 0 0" xyz="0 0 0" />
      <geometry>
        <mesh filename="package://robot_description/meshes/roller.stl" scale="0.001 0.001 0.001" />
      </geometry>
      <material name="grey" />
    </visual>
    <collision>
      <origin rpy="0 0 0" xyz="0 0 0" />
      <geometry>
        <sphere radius="0.0097" />
      </geometry>
    </collision>
    <collision>
      <origin rpy="0 0 0" xyz="0 0 0.00792" />
      <geometry>
        <sphere radius="0.00952" />
      </geometry>
    </collision>
    <collision>
      <origin rpy="0 0 0" xyz="0 0 -0.00792" />
      <geometry>
        <sphere radius="0.00952" />
      </geometry>
    </collision>
    <collision>
      <origin rpy="0 0 0" xyz="0 0 0.01584" />
      <geometry>
        <sphere radius="0.008985" />
      </geometry>
    </collision>
    <collision>
      <origin rpy="0 0 0" xyz="0 0 -0.01584" />
      <geometry>
        <sphere radius="0.008985" />
      </geometry>
    </collision>
  </link>
  <joint name="rear_left_roller_3_joint" type="continuous">
    <origin rpy="0.6801747615878317 -0.392699081698724 0" xyz="0.03360178566683622 -0.019399999999999994 0" />
    <parent link="rear_left_mecanum_link" />
    <child link="rear_left_roller_3" />
    <axis xyz="0.0 0.0 1.0" />
  </joint>
  <link name="rear_left_roller_4">
    <visual>
      <origin rpy="0 0 0" xyz="0 0 0" />
      <geometry>
        <mesh filename="package://robot_description/meshes/roller.stl" scale="0.001 0.001 0.001" />
      </geometry>
      <material name="grey" />
    </visual>
    <collision>
      <origin rpy="0 0 0" xyz="0 0 0" />
      <geometry>
        <sphere radius="0.0097" />
      </geometry>
    </collision>
    <collision>
      <origin rpy="0 0 0" xyz="0 0 0.00792" />
      <geometry>
        <sphere radius="0.00952" />
      </geometry>
    </collision>
    <collision>
      <origin rpy="0 0 0" xyz="0 0 -0.00792" />
      <geometry>
        <sphere radius="0.00952" />
      </geometry>
    </collision>
    <collision>
      <origin rpy="0 0 0" xyz="0 0 0.01584" />
      <geometry>
        <sphere radius="0.008985" />
      </geometry>
    </collision>
    <collision>
      <origin rpy="0 0 0" xyz="0 0 -0.01584" />
      <geometry>
        <sphere radius="0.008985" />
      </geometry>
    </collision>
  </link>
  <joint name="rear_left_roller_4_joint" type="continuous">
    <origin rpy="0.26862199241291235 -0.7380328585233872 0" xyz="0.013270381561035953 -0.03646007368649325 0" />
    <parent link="rear_left_mecanum_link" />
    <child link="rear_left_roller_4" />
    <axis xyz="0.0 0.0 1.0" />
  </joint>
  <link name="rear_left_roller_5">
    <visual>
      <origin rpy="0 0 0" xyz="0 0 0" />
      <geometry>
        <mesh filename="package://robot_description/meshes/roller.stl" scale="0.001 0.001 0.001" />
      </geometry>
      <material name="grey" />
    </visual>
    <collision>
      <origin rpy="0 0 0" xyz="0 0 0" />
      <geometry>
        <sphere radius="0.0097" />
      </geometry>
    </collision>
    <collision>
      <origin rpy="0 0 0" xyz="0 0 0.00792" />
      <geometry>
        <sphere radius="0.00952" />
      </geometry>
    </collision>
    <collision>
      <origin rpy="0 0 0" xyz="0 0 -0.00792" />
      <geometry>
        <sphere radius="0.00952" />
      </geometry>
    </collision>
    <collision>
      <origin rpy="0 0 0" xyz="0 0 0.01584" />
      <geometry>
        <sphere radius="0.008985" />
      </geometry>
    </collision>
    <collision>
      <origin rpy="0 0 0" xyz="0 0 -0.01584" />
      <geometry>
        <sphere radius="0.008985" />
      </geometry>
    </collision>
  </link>
  <joint name="rear_left_roller_5_joint" type="continuous">
    <origin rpy="-0.2686219924129122 -0.7380328585233873 0" xyz="-0.013270381561035945 -0.03646007368649325 0" />
    <parent link="rear_left_mecanum_link" />
    <child link="rear_left_roller_5" />
    <axis xyz="0.0 0.0 1.0" />
  </joint>
  <link name="rear_left_roller_6">
    <visual>
      <origin rpy="0 0 0" xyz="0 0 0" />
      <geometry>
        <mesh filename="package://robot_description/meshes/roller.stl" scale="0.001 0.001 0.001" />
      </geometry>
      <material name="grey" />
    </visual>
    <collision>
      <origin rpy="0 0 0" xyz="0 0 0" />
      <geometry>
        <sphere radius="0.0097" />
      </geometry>
    </collision>
    <collision>
      <origin rpy="0 0 0" xyz="0 0 0.00792" />
      <geometry>
        <sphere radius="0.00952" />
      </geometry>
    </collision>
    <collision>
      <origin rpy="0 0 0" xyz="0 0 -0.00792" />
      <geometry>
        <sphere radius="0.00952" />
      </geometry>
    </collision>
    <collision>
      <origin rpy="0 0 0" xyz="0 0 0.01584" />
      <geometry>
        <sphere radius="0.008985" />
      </geometry>
    </collision>
    <collision>
      <origin rpy="0 0 0" xyz="0 0 -0.01584" />
      <geometry>
        <sphere radius="0.008985" />
      </geometry>
    </collision>
  </link>
  <joint name="rear_left_roller_6_joint" type="continuous">
    <origin rpy="-0.6801747615878314 -0.3926990816987245 0" xyz="-0.03360178566683621 -0.019400000000000018 0" />
    <parent link="rear_left_mecanum_link" />
    <child link="rear_left_roller_6" />
    <axis xyz="0.0 0.0 1.0" />
  </joint>
  <link name="rear_left_roller_7">
    <visual>
      <origin rpy="0 0 0" xyz="0 0 0" />
      <geometry>
        <mesh filename="package://robot_description/meshes/roller.stl" scale="0.001 0.001 0.001" />
      </geometry>
      <material name="grey" />
    </visual>
    <collision>
      <origin rpy="0 0 0" xyz="0 0 0" />
      <geometry>
        <sphere radius="0.0097" />
      </geometry>
    </collision>
    <collision>
      <origin rpy="0 0 0" xyz="0 0 0.00792" />
      <geometry>
        <sphere radius="0.00952" />
      </geometry>
    </collision>
    <collision>
      <origin rpy="0 0 0" xyz="0 0 -0.00792" />
      <geometry>
        <sphere radius="0.00952" />
      </geometry>
    </collision>
    <collision>
      <origin rpy="0 0 0" xyz="0 0 0.01584" />
      <geometry>
        <sphere radius="0.008985" />
      </geometry>
    </collision>
    <collision>
      <origin rpy="0 0 0" xyz="0 0 -0.01584" />
      <geometry>
        <sphere radius="0.008985" />
      </geometry>
    </collision>
  </link>
  <joint name="rear_left_roller_7_joint" type="continuous">
    <origin rpy="-0.7734662005153561 0.13638295981692058 0" xyz="-0.038210540816873674 0.006737549293476883 0" />
    <parent link="rear_left_mecanum_link" />
    <child link="rear_left_roller_7" />
    <axis xyz="0.0 0.0 1.0" />
  </joint>
  <link name="rear_left_roller_8">
    <visual>
      <origin rpy="0 0 0" xyz="0 0 0" />
      <geometry>
        <mesh filename="package://robot_description/meshes/roller.stl" scale="0.001 0.001 0.001" />
      </geometry>
      <material name="grey" />
    </visual>
    <collision>
      <origin rpy="0 0 0" xyz="0 0 0" />
      <geometry>
        <sphere radius="0.0097" />
      </geometry>
    </collision>
    <collision>
      <origin rpy="0 0 0" xyz="0 0 0.00792" />
      <geometry>
        <sphere radius="0.00952" />
      </geometry>
    </collision>
    <collision>
      <origin rpy="0 0 0" xyz="0 0 -0.00792" />
      <geometry>
        <sphere radius="0.00952" />
      </geometry>
    </collision>
    <collision>
      <origin rpy="0 0 0" xyz="0 0 0.01584" />
      <geometry>
        <sphere radius="0.008985" />
      </geometry>
    </collision>
    <collision>
      <origin rpy="0 0 0" xyz="0 0 -0.01584" />
      <geometry>
        <sphere radius="0.008985" />
      </geometry>
    </collision>
  </link>
  <joint name="rear_left_roller_8_joint" type="continuous">
    <origin rpy="-0.504844208102444 0.6016498987064662 0" xyz="-0.024940159255837736 0.02972252439301634 0" />
    <parent link="rear_left_mecanum_link" />
    <child link="rear_left_roller_8" />
    <axis xyz="0.0 0.0 1.0" />
  </joint>
  <link name="front_left_mecanum_link">
    <inertial>
      <origin rpy="0 1.5707963267948966 0" xyz="0 0 0" />
      <mass value="0.136" />
      <inertia ixx="7.117696e-05" ixy="0.0" ixz="0.0" iyy="7.117696e-05" iyz="0.0" izz="0.00010236992" />
    </inertial>
    <visual>
      <origin rpy="0 0 0" xyz="0 0 0" />
      <geometry>
        <mesh filename="package://robot_description/meshes/mec_hub_2.stl" scale="0.001 0.001 0.001" />
      </geometry>
      <material name="orange" />
    </visual>
    <collision>
      <origin rpy="0 0 0" xyz="0 0 0" />
      <geometry>
        <cylinder length="0.042" radius="0.0388" />
      </geometry>
    </collision>
  </link>
  <joint name="front_left_mecanum_joint" type="continuous">
    <origin rpy="0 1.5707963267948966 0" xyz="-0.108 0.145 -0.121" />
    <parent link="chassis_link" />
    <child link="front_left_mecanum_link" />
    <axis xyz="0.0 0.0 -1.0" />
  </joint>
  <link name="front_left_roller_0">
    <visual>
      <origin rpy="0 0 0" xyz="0 0 0" />
      <geometry>
        <mesh filename="package://robot_description/meshes/roller.stl" scale="0.001 0.001 0.001" />
      </geometry>
      <material name="grey" />
    </visual>
    <collision>
      <origin rpy="0 0 0" xyz="0 0 0" />
      <geometry>
        <sphere radius="0.0097" />
      </geometry>
    </collision>
    <collision>
      <origin rpy="0 0 0" xyz="0 0 0.00792" />
      <geometry>
        <sphere radius="0.00952" />
      </geometry>
    </collision>
    <collision>
      <origin rpy="0 0 0" xyz="0 0 -0.00792" />
      <geometry>
        <sphere radius="0.00952" />
      </geometry>
    </collision>
    <collision>
      <origin rpy="0 0 0" xyz="0 0 0.01584" />
      <geometry>
        <sphere radius="0.008985" />
      </geometry>
    </collision>
    <collision>
      <origin rpy="0 0 0" xyz="0 0 -0.01584" />
      <geometry>
        <sphere radius="0.008985" />
      </geometry>
    </collision>
  </link>
  <joint name="front_left_roller_0_joint" type="continuous">
    <origin rpy="-0.0 -0.7853981633974483 0" xyz="0.0 0.0388 0" />
    <parent link="front_left_mecanum_link" />
    <child link="front_left_roller_0" />
    <axis xyz="0.0 0.0 1.0" />
  </joint>
  <link name="front_left_roller_1">
    <visual>
      <origin rpy="0 0 0" xyz="0 0 0" />
      <geometry>
        <mesh filename="package://robot_description/meshes/roller.stl" scale="0.001 0.001 0.001" />
      </geometry>
      <material name="grey" />
    </visual>
    <collision>
      <origin rpy="0 0 0" xyz="0 0 0" />
      <geometry>
        <sphere radius="0.0097" />
      </geometry>
    </collision>
    <collision>
      <origin rpy="0 0 0" xyz="0 0 0.00792" />
      <geometry>
        <sphere radius="0.00952" />
      </geometry>
    </collision>
    <collision>
      <origin rpy="0 0 0" xyz="0 0 -0.00792" />
      <geometry>
        <sphere radius="0.00952" />
      </geometry>
    </collision>
    <collision>
      <origin rpy="0 0 0" xyz="0 0 0.01584" />
      <geometry>
        <sphere radius="0.008985" />
      </geometry>
    </collision>
    <collision>
      <origin rpy="0 0 0" xyz="0 0 -0.01584" />
      <geometry>
        <sphere radius="0.008985" />
      </geometry>
    </collision>
  </link>
  <joint name="front_left_roller_1_joint" type="continuous">
    <origin rpy="-0.5048442081024438 -0.6016498987064663 0" xyz="0.024940159255837722 0.02972252439301635 0" />
    <parent link="front_left_mecanum_link" />
    <child link="front_left_roller_1" />
    <axis xyz="0.0 0.0 1.0" />
  </joint>
  <link name="front_left_roller_2">
    <visual>
      <origin rpy="0 0 0" xyz="0 0 0" />
      <geometry>
        <mesh filename="package://robot_description/meshes/roller.stl" scale="0.001 0.001 0.001" />
      </geometry>
      <material name="grey" />
    </visual>
    <collision>
      <origin rpy="0 0 0" xyz="0 0 0" />
      <geometry>
        <sphere radius="0.0097" />
      </geometry>
    </collision>
    <collision>
      <origin rpy="0 0 0" xyz="0 0 0.00792" />
      <geometry>
        <sphere radius="0.00952" />
      </geometry>
    </collision>
    <collision>
      <origin rpy="0 0 0" xyz="0 0 -0.00792" />
      <geometry>
        <sphere radius="0.00952" />
      </geometry>
    </collision>
    <collision>
      <origin rpy="0 0 0" xyz="0 0 0.01584" />
      <geometry>
        <sphere radius="0.008985" />
      </geometry>
    </collision>
    <collision>
      <origin rpy="0 0 0" xyz="0 0 -0.01584" />
      <geometry>
        <sphere radius="0.008985" />
      </geometry>
    </collision>
  </link>
  <joint name="front_left_roller_2_joint" type="continuous">
    <origin rpy="-0.7734662005153561 -0.13638295981692095 0" xyz="0.038210540816873674 0.0067375492934769006 0" />
    <parent link="front_left_mecanum_link" />
    <child link="front_left_roller_2" />
    <axis xyz="0.0 0.0 1.0" />
  </joint>
  <link name="front_left_roller_3">
    <visual>
      <origin rpy="0 0 0" xyz="0 0 0" />
      <geometry>
        <mesh filename="package://robot_description/meshes/roller.stl" scale="0.001 0.001 0.001" />
      </geometry>
      <material name="grey" />
    </visual>
    <collision>
      <origin rpy="0 0 0" xyz="0 0 0" />
      <geometry>
        <sphere radius="0.0097" />
      </geometry>
    </collision>
    <collision>
      <origin rpy="0 0 0" xyz="0 0 0.00792" />
      <geometry>
        <sphere radius="0.00952" />
      </geometry>
    </collision>
    <collision>
      <origin rpy="0 0 0" xyz="0 0 -0.00792" />
      <geometry>
        <sphere radius="0.00952" />
      </geometry>
    </collision>
    <collision>
      <origin rpy="0 0 0" xyz="0 0 0.01584" />
      <geometry>
        <sphere radius="0.008985" />
      </geometry>
    </collision>
    <collision>
      <origin rpy="0 0 0" xyz="0 0 -0.01584" />
      <geometry>
        <sphere radius="0.008985" />
      </geometry>
    </collision>
  </link>
  <joint name="front_left_roller_3_joint" type="continuous">
    <origin rpy="-0.6801747615878317 0.392699081698724 0" xyz="0.03360178566683622 -0.019399999999999994 0" />
    <parent link="front_left_mecanum_link" />
    <child link="front_left_roller_3" />
    <axis xyz="0.0 0.0 1.0" />
  </joint>
  <link name="front_left_roller_4">
    <visual>
      <origin rpy="0 0 0" xyz="0 0 0" />
      <geometry>
        <mesh filename="package://robot_description/meshes/roller.stl" scale="0.001 0.001 0.001" />
      </geometry>
      <material name="grey" />
    </visual>
    <collision>
      <origin rpy="0 0 0" xyz="0 0 0" />
      <geometry>
        <sphere radius="0.0097" />
      </geometry>
    </collision>
    <collision>
      <origin rpy="0 0 0" xyz="0 0 0.00792" />
      <geometry>
        <sphere radius="0.00952" />
      </geometry>
    </collision>
    <collision>
      <origin rpy="0 0 0" xyz="0 0 -0.00792" />
      <geometry>
        <sphere radius="0.00952" />
      </geometry>
    </collision>
    <collision>
      <origin rpy="0 0 0" xyz="0 0 0.01584" />
      <geometry>
        <sphere radius="0.008985" />
      </geometry>
    </collision>
    <collision>
      <origin rpy="0 0 0" xyz="0 0 -0.01584" />
      <geometry>
        <sphere radius="0.008985" />
      </geometry>
    </collision>
  </link>
  <joint name="front_left_roller_4_joint" type="continuous">
    <origin rpy="-0.26862199241291235 0.7380328585233872 0" xyz="0.013270381561035953 -0.03646007368649325 0" />
    <parent link="front_left_mecanum_link" />
    <child link="front_left_roller_4" />
    <axis xyz="0.0 0.0 1.0" />
  </joint>
  <link name="front_left_roller_5">
    <visual>
      <origin rpy="0 0 0" xyz="0 0 0" />
      <geometry>
        <mesh filename="package://robot_description/meshes/roller.stl" scale="0.001 0.001 0.001" />
      </geometry>
      <material name="grey" />
    </visual>
    <collision>
      <origin rpy="0 0 0" xyz="0 0 0" />
      <geometry>
        <sphere radius="0.0097" />
      </geometry>
    </collision>
    <collision>
      <origin rpy="0 0 0" xyz="0 0 0.00792" />
      <geometry>
        <sphere radius="0.00952" />
      </geometry>
    </collision>
    <collision>
      <origin rpy="0 0 0" xyz="0 0 -0.00792" />
      <geometry>
        <sphere radius="0.00952" />
      </geometry>
    </collision>
    <collision>
      <origin rpy="0 0 0" xyz="0 0 0.01584" />
      <geometry>
        <sphere radius="0.008985" />
      </geometry>
    </collision>
    <collision>
      <origin rpy="0 0 0" xyz="0 0 -0.01584" />
      <geometry>
        <sphere radius="0.008985" />
      </geometry>
    </collision>
  </link>
  <joint name="front_left_roller_5_joint" type="continuous">
    <origin rpy="0.2686219924129122 0.7380328585233873 0" xyz="-0.013270381561035945 -0.03646007368649325 0" />
    <parent link="front_left_mecanum_link" />
    <child link="front_left_roller_5" />
    <axis xyz="0.0 0.0 1.0" />
  </joint>
  <link name="front_left_roller_6">
    <visual>
      <origin rpy="0 0 0" xyz="0 0 0" />
      <geometry>
        <mesh filename="package://robot_description/meshes/roller.stl" scale="0.001 0.001 0.001" />
      </geometry>
      <material name="grey" />
    </visual>
    <collision>
      <origin rpy="0 0 0" xyz="0 0 0" />
      <geometry>
        <sphere radius="0.0097" />
      </geometry>
    </collision>
    <collision>
      <origin rpy="0 0 0" xyz="0 0 0.00792" />
      <geometry>
        <sphere radius="0.00952" />
      </geometry>
    </collision>
    <collision>
      <origin rpy="0 0 0" xyz="0 0 -0.00792" />
      <geometry>
        <sphere radius="0.00952" />
      </geometry>
    </collision>
    <collision>
      <origin rpy="0 0 0" xyz="0 0 0.01584" />
      <geometry>
        <sphere radius="0.008985" />
      </geometry>
    </collision>
    <collision>
      <origin rpy="0 0 0" xyz="0 0 -0.01584" />
      <geometry>
        <sphere radius="0.008985" />
      </geometry>
    </collision>
  </link>
  <joint name="front_left_roller_6_joint" type="continuous">
    <origin rpy="0.6801747615878314 0.3926990816987245 0" xyz="-0.03360178566683621 -0.019400000000000018 0" />
    <parent link="front_left_mecanum_link" />
    <child link="front_left_roller_6" />
    <axis xyz="0.0 0.0 1.0" />
  </joint>
  <link name="front_left_roller_7">
    <visual>
      <origin rpy="0 0 0" xyz="0 0 0" />
      <geometry>
        <mesh filename="package://robot_description/meshes/roller.stl" scale="0.001 0.001 0.001" />
      </geometry>
      <material name="grey" />
    </visual>
    <collision>
      <origin rpy="0 0 0" xyz="0 0 0" />
      <geometry>
        <sphere radius="0.0097" />
      </geometry>
    </collision>
    <collision>
      <origin rpy="0 0 0" xyz="0 0 0.00792" />
      <geometry>
        <sphere radius="0.00952" />
      </geometry>
    </collision>
    <collision>
      <origin rpy="0 0 0" xyz="0 0 -0.00792" />
      <geometry>
        <sphere radius="0.00952" />
      </geometry>
    </collision>
    <collision>
      <origin rpy="0 0 0" xyz="0 0 0.01584" />
      <geometry>
        <sphere radius="0.008985" />
      </geometry>
    </collision>
    <collision>
      <origin rpy="0 0 0" xyz="0 0 -0.01584" />
      <geometry>
        <sphere radius="0.008985" />
      </geometry>
    </collision>
  </link>
  <joint name="front_left_roller_7_joint" type="continuous">
    <origin rpy="0.7734662005153561 -0.13638295981692058 0" xyz="-0.038210540816873674 0.006737549293476883 0" />
    <parent link="front_left_mecanum_link" />
    <child link="front_left_roller_7" />
    <axis xyz="0.0 0.0 1.0" />
  </joint>
  <link name="front_left_roller_8">
    <visual>
      <origin rpy="0 0 0" xyz="0 0 0" />
      <geometry>
        <mesh filename="package://robot_description/meshes/roller.stl" scale="0.001 0.001 0.001" />
      </geometry>
      <material name="grey" />
    </visual>
    <collision>
      <origin rpy="0 0 0" xyz="0 0 0" />
      <geometry>
        <sphere radius="0.0097" />
      </geometry>
    </collision>
    <collision>
      <origin rpy="0 0 0" xyz="0 0 0.00792" />
      <geometry>
        <sphere radius="0.00952" />
      </geometry>
    </collision>
    <collision>
      <origin rpy="0 0 0" xyz="0 0 -0.00792" />
      <geometry>
        <sphere radius="0.00952" />
      </geometry>
    </collision>
    <collision>
      <origin rpy="0 0 0" xyz="0 0 0.01584" />
      <geometry>
        <sphere radius="0.008985" />
      </geometry>
    </collision>
    <collision>
      <origin rpy="0 0 0" xyz="0 0 -0.01584" />
      <geometry>
        <sphere radius="0.008985" />
      </geometry>
    </collision>
  </link>
  <joint name="front_left_roller_8_joint" type="continuous">
    <origin rpy="0.504844208102444 -0.6016498987064662 0" xyz="-0.024940159255837736 0.02972252439301634 0" />
    <parent link="front_left_mecanum_link" />
    <child link="front_left_roller_8" />
    <axis xyz="0.0 0.0 1.0" />
  </joint>
  <link name="rear_right_mecanum_link">
    <inertial>
      <origin rpy="0 1.5707963267948966 0" xyz="0 0 0" />
      <mass value="0.136" />
      <inertia ixx="7.117696e-05" ixy="0.0" ixz="0.0" iyy="7.117696e-05" iyz="0.0" izz="0.00010236992" />
    </inertial>
    <visual>
      <origin rpy="0 0 0" xyz="0 0 0" />
      <geometry>
        <mesh filename="package://robot_description/meshes/mec_hub_2.stl" scale="0.001 0.001 0.001" />
      </geometry>
      <material name="orange" />
    </visual>
    <collision>
      <origin rpy="0 0 0" xyz="0 0 0" />
      <geometry>
        <cylinder length="0.042" radius="0.0388" />
      </geometry>
    </collision>
  </link>
  <joint name="rear_right_mecanum_joint" type="continuous">
    <origin rpy="0 -1.5707963267948966 0" xyz="0.108 -0.145 -0.121" />
    <parent link="chassis_link" />
    <child link="rear_right_mecanum_link" />
    <axis xyz="0.0 0.0 1.0" />
  </joint>
  <link name="rear_right_roller_0">
    <visual>
      <origin rpy="0 0 0" xyz="0 0 0" />
      <geometry>
        <mesh filename="package://robot_description/meshes/roller.stl" scale="0.001 0.001 0.001" />
      </geometry>
      <material name="grey" />
    </visual>
    <collision>
      <origin rpy="0 0 0" xyz="0 0 0" />
      <geometry>
        <sphere radius="0.0097" />
      </geometry>
    </collision>
    <collision>
      <origin rpy="0 0 0" xyz="0 0 0.00792" />
      <geometry>
        <sphere radius="0.00952" />
      </geometry>
    </collision>
    <collision>
      <origin rpy="0 0 0" xyz="0 0 -0.00792" />
      <geometry>
        <sphere radius="0.00952" />
      </geometry>
    </collision>
    <collision>
      <origin rpy="0 0 0" xyz="0 0 0.01584" />
      <geometry>
        <sphere radius="0.008985" />
      </geometry>
    </collision>
    <collision>
      <origin rpy="0 0 0" xyz="0 0 -0.01584" />
      <geometry>
        <sphere radius="0.008985" />
      </geometry>
    </collision>
  </link>
  <joint name="rear_right_roller_0_joint" type="continuous">
    <origin rpy="-0.0 -0.7853981633974483 0" xyz="0.0 0.0388 0" />
    <parent link="rear_right_mecanum_link" />
    <child link="rear_right_roller_0" />
    <axis xyz="0.0 0.0 1.0" />
  </joint>
  <link name="rear_right_roller_1">
    <visual>
      <origin rpy="0 0 0" xyz="0 0 0" />
      <geometry>
        <mesh filename="package://robot_description/meshes/roller.stl" scale="0.001 0.001 0.001" />
      </geometry>
      <material name="grey" />
    </visual>
    <collision>
      <origin rpy="0 0 0" xyz="0 0 0" />
      <geometry>
        <sphere radius="0.0097" />
      </geometry>
    </collision>
    <collision>
      <origin rpy="0 0 0" xyz="0 0 0.00792" />
      <geometry>
        <sphere radius="0.00952" />
      </geometry>
    </collision>
    <collision>
      <origin rpy="0 0 0" xyz="0 0 -0.00792" />
      <geometry>
        <sphere radius="0.00952" />
      </geometry>
    </collision>
    <collision>
      <origin rpy="0 0 0" xyz="0 0 0.01584" />
      <geometry>
        <sphere radius="0.008985" />
      </geometry>
    </collision>
    <collision>
      <origin rpy="0 0 0" xyz="0 0 -0.01584" />
      <geometry>
        <sphere radius="0.008985" />
      </geometry>
    </collision>
  </link>
  <joint name="rear_right_roller_1_joint" type="continuous">
    <origin rpy="-0.5048442081024438 -0.6016498987064663 0" xyz="0.024940159255837722 0.02972252439301635 0" />
    <parent link="rear_right_mecanum_link" />
    <child link="rear_right_roller_1" />
    <axis xyz="0.0 0.0 1.0" />
  </joint>
  <link name="rear_right_roller_2">
    <visual>
      <origin rpy="0 0 0" xyz="0 0 0" />
      <geometry>
        <mesh filename="package://robot_description/meshes/roller.stl" scale="0.001 0.001 0.001" />
      </geometry>
      <material name="grey" />
    </visual>
    <collision>
      <origin rpy="0 0 0" xyz="0 0 0" />
      <geometry>
        <sphere radius="0.0097" />
      </geometry>
    </collision>
    <collision>
      <origin rpy="0 0 0" xyz="0 0 0.00792" />
      <geometry>
        <sphere radius="0.00952" />
      </geometry>
    </collision>
    <collision>
      <origin rpy="0 0 0" xyz="0 0 -0.00792" />
      <geometry>
        <sphere radius="0.00952" />
      </geometry>
    </collision>
    <collision>
      <origin rpy="0 0 0" xyz="0 0 0.01584" />
      <geometry>
        <sphere radius="0.008985" />
      </geometry>
    </collision>
    <collision>
      <origin rpy="0 0 0" xyz="0 0 -0.01584" />
      <geometry>
        <sphere radius="0.008985" />
      </geometry>
    </collision>
  </link>
  <joint name="rear_right_roller_2_joint" type="continuous">
    <origin rpy="-0.7734662005153561 -0.13638295981692095 0" xyz="0.038210540816873674 0.0067375492934769006 0" />
    <parent link="rear_right_mecanum_link" />
    <child link="rear_right_roller_2" />
    <axis xyz="0.0 0.0 1.0" />
  </joint>
  <link name="rear_right_roller_3">
    <visual>
      <origin rpy="0 0 0" xyz="0 0 0" />
      <geometry>
        <mesh filename="package://robot_description/meshes/roller.stl" scale="0.001 0.001 0.001" />
      </geometry>
      <material name="grey" />
    </visual>
    <collision>
      <origin rpy="0 0 0" xyz="0 0 0" />
      <geometry>
        <sphere radius="0.0097" />
      </geometry>
    </collision>
    <collision>
      <origin rpy="0 0 0" xyz="0 0 0.00792" />
      <geometry>
        <sphere radius="0.00952" />
      </geometry>
    </collision>
    <collision>
      <origin rpy="0 0 0" xyz="0 0 -0.00792" />
      <geometry>
        <sphere radius="0.00952" />
      </geometry>
    </collision>
    <collision>
      <origin rpy="0 0 0" xyz="0 0 0.01584" />
      <geometry>
        <sphere radius="0.008985" />
      </geometry>
    </collision>
    <collision>
      <origin rpy="0 0 0" xyz="0 0 -0.01584" />
      <geometry>
        <sphere radius="0.008985" />
      </geometry>
    </collision>
  </link>
  <joint name="rear_right_roller_3_joint" type="continuous">
    <origin rpy="-0.6801747615878317 0.392699081698724 0" xyz="0.03360178566683622 -0.019399999999999994 0" />
    <parent link="rear_right_mecanum_link" />
    <child link="rear_right_roller_3" />
    <axis xyz="0.0 0.0 1.0" />
  </joint>
  <link name="rear_right_roller_4">
    <visual>
      <origin rpy="0 0 0" xyz="0 0 0" />
      <geometry>
        <mesh filename="package://robot_description/meshes/roller.stl" scale="0.001 0.001 0.001" />
      </geometry>
      <material name="grey" />
    </visual>
    <collision>
      <origin rpy="0 0 0" xyz="0 0 0" />
      <geometry>
        <sphere radius="0.0097" />
      </geometry>
    </collision>
    <collision>
      <origin rpy="0 0 0" xyz="0 0 0.00792" />
      <geometry>
        <sphere radius="0.00952" />
      </geometry>
    </collision>
    <collision>
      <origin rpy="0 0 0" xyz="0 0 -0.00792" />
      <geometry>
        <sphere radius="0.00952" />
      </geometry>
    </collision>
    <collision>
      <origin rpy="0 0 0" xyz="0 0 0.01584" />
      <geometry>
        <sphere radius="0.008985" />
      </geometry>
    </collision>
    <collision>
      <origin rpy="0 0 0" xyz="0 0 -0.01584" />
      <geometry>
        <sphere radius="0.008985" />
      </geometry>
    </collision>
  </link>
  <joint name="rear_right_roller_4_joint" type="continuous">
    <origin rpy="-0.26862199241291235 0.7380328585233872 0" xyz="0.013270381561035953 -0.03646007368649325 0" />
    <parent link="rear_right_mecanum_link" />
    <child link="rear_right_roller_4" />
    <axis xyz="0.0 0.0 1.0" />
  </joint>
  <link name="rear_right_roller_5">
    <visual>
      <origin rpy="0 0 0" xyz="0 0 0" />
      <geometry>
        <mesh filename="package://robot_description/meshes/roller.stl" scale="0.001 0.001 0.001" />
      </geometry>
      <material name="grey" />
    </visual>
    <collision>
      <origin rpy="0 0 0" xyz="0 0 0" />
      <geometry>
        <sphere radius="0.0097" />
      </geometry>
    </collision>
    <collision>
      <origin rpy="0 0 0" xyz="0 0 0.00792" />
      <geometry>
        <sphere radius="0.00952" />
      </geometry>
    </collision>
    <collision>
      <origin rpy="0 0 0" xyz="0 0 -0.00792" />
      <geometry>
        <sphere radius="0.00952" />
      </geometry>
    </collision>
    <collision>
      <origin rpy="0 0 0" xyz="0 0 0.01584" />
      <geometry>
        <sphere radius="0.008985" />
      </geometry>
    </collision>
    <collision>
      <origin rpy="0 0 0" xyz="0 0 -0.01584" />
      <geometry>
        <sphere radius="0.008985" />
      </geometry>
    </collision>
  </link>
  <joint name="rear_right_roller_5_joint" type="continuous">
    <origin rpy="0.2686219924129122 0.7380328585233873 0" xyz="-0.013270381561035945 -0.03646007368649325 0" />
    <parent link="rear_right_mecanum_link" />
    <child link="rear_right_roller_5" />
    <axis xyz="0.0 0.0 1.0" />
  </joint>
  <link name="rear_right_roller_6">
    <visual>
      <origin rpy="0 0 0" xyz="0 0 0" />
      <geometry>
        <mesh filename="package://robot_description/meshes/roller.stl" scale="0.001 0.001 0.001" />
      </geometry>
      <material name="grey" />
    </visual>
    <collision>
      <origin rpy="0 0 0" xyz="0 0 0" />
      <geometry>
        <sphere radius="0.0097" />
      </geometry>
    </collision>
    <collision>
      <origin rpy="0 0 0" xyz="0 0 0.00792" />
      <geometry>
        <sphere radius="0.00952" />
      </geometry>
    </collision>
    <collision>
      <origin rpy="0 0 0" xyz="0 0 -0.00792" />
      <geometry>
        <sphere radius="0.00952" />
      </geometry>
    </collision>
    <collision>
      <origin rpy="0 0 0" xyz="0 0 0.01584" />
      <geometry>
        <sphere radius="0.008985" />
      </geometry>
    </collision>
    <collision>
      <origin rpy="0 0 0" xyz="0 0 -0.01584" />
      <geometry>
        <sphere radius="0.008985" />
      </geometry>
    </collision>
  </link>
  <joint name="rear_right_roller_6_joint" type="continuous">
    <origin rpy="0.6801747615878314 0.3926990816987245 0" xyz="-0.03360178566683621 -0.019400000000000018 0" />
    <parent link="rear_right_mecanum_link" />
    <child link="rear_right_roller_6" />
    <axis xyz="0.0 0.0 1.0" />
  </joint>
  <link name="rear_right_roller_7">
    <visual>
      <origin rpy="0 0 0" xyz="0 0 0" />
      <geometry>
        <mesh filename="package://robot_description/meshes/roller.stl" scale="0.001 0.001 0.001" />
      </geometry>
      <material name="grey" />
    </visual>
    <collision>
      <origin rpy="0 0 0" xyz="0 0 0" />
      <geometry>
        <sphere radius="0.0097" />
      </geometry>
    </collision>
    <collision>
      <origin rpy="0 0 0" xyz="0 0 0.00792" />
      <geometry>
        <sphere radius="0.00952" />
      </geometry>
    </collision>
    <collision>
      <origin rpy="0 0 0" xyz="0 0 -0.00792" />
      <geometry>
        <sphere radius="0.00952" />
      </geometry>
    </collision>
    <collision>
      <origin rpy="0 0 0" xyz="0 0 0.01584" />
      <geometry>
        <sphere radius="0.008985" />
      </geometry>
    </collision>
    <collision>
      <origin rpy="0 0 0" xyz="0 0 -0.01584" />
      <geometry>
        <sphere radius="0.008985" />
      </geometry>
    </collision>
  </link>
  <joint name="rear_right_roller_7_joint" type="continuous">
    <origin rpy="0.7734662005153561 -0.13638295981692058 0" xyz="-0.038210540816873674 0.006737549293476883 0" />
    <parent link="rear_right_mecanum_link" />
    <child link="rear_right_roller_7" />
    <axis xyz="0.0 0.0 1.0" />
  </joint>
  <link name="rear_right_roller_8">
    <visual>
      <origin rpy="0 0 0" xyz="0 0 0" />
      <geometry>
        <mesh filename="package://robot_description/meshes/roller.stl" scale="0.001 0.001 0.001" />
      </geometry>
      <material name="grey" />
    </visual>
    <collision>
      <origin rpy="0 0 0" xyz="0 0 0" />
      <geometry>
        <sphere radius="0.0097" />
      </geometry>
    </collision>
    <collision>
      <origin rpy="0 0 0" xyz="0 0 0.00792" />
      <geometry>
        <sphere radius="0.00952" />
      </geometry>
    </collision>
    <collision>
      <origin rpy="0 0 0" xyz="0 0 -0.00792" />
      <geometry>
        <sphere radius="0.00952" />
      </geometry>
    </collision>
    <collision>
      <origin rpy="0 0 0" xyz="0 0 0.01584" />
      <geometry>
        <sphere radius="0.008985" />
      </geometry>
    </collision>
    <collision>
      <origin rpy="0 0 0" xyz="0 0 -0.01584" />
      <geometry>
        <sphere radius="0.008985" />
      </geometry>
    </collision>
  </link>
  <joint name="rear_right_roller_8_joint" type="continuous">
    <origin rpy="0.504844208102444 -0.6016498987064662 0" xyz="-0.024940159255837736 0.02972252439301634 0" />
    <parent link="rear_right_mecanum_link" />
    <child link="rear_right_roller_8" />
    <axis xyz="0.0 0.0 1.0" />
  </joint>
</robot>