<robot name="examplo">
    <!-- Specify some standard inertial calculations https://en.wikipedia.org/wiki/List_of_moments_of_inertia -->
    <!-- These make use of xacro's mathematical functionality -->
    <material name="silver">
        <color rgba="0.700 0.700 0.700 1.000" />
    </material>
    <link name="base_link" />
    <link name="chassis_link">
        <inertial>
            <origin rpy="0 0 0" xyz="0 0 -0.0675" />
            <mass value="2.45" />
            <inertia ixx="0.025954687500000004" ixy="0.0" ixz="0.0" iyy="0.0103359375" iyz="0.0" izz="0.028848750000000003" />
        </inertial>
        <visual>
            <origin rpy="0 0 0" xyz="0 0 0" />
            <geometry>
                <mesh filename="package://robot_description/meshes/chassis.stl" scale="0.001 0.001 0.001" />
            </geometry>
            <material name="silver" />
        </visual>
        <collision>
            <origin rpy="0 0 0" xyz="0 0 -0.0675" />
            <geometry>
                <box size="0.18 0.33 0.135" />
            </geometry>
        </collision>
    </link>
    <gazebo reference="chassis">
        <material>Gazebo/Blue</material>
    </gazebo>
    <joint name="chassis_joint" type="fixed">
        <parent link="base_link" />
        <child link="chassis_link" />
        <origin xyz="0 0 0" />
    </joint>
    <link name="front_right_wheel_link">
        <inertial>
            <origin rpy="0 1.5707963267948966 0" xyz="0 0 0" />
            <mass value="0.136" />
            <inertia ixx="9.509800000000002e-05" ixy="0.0" ixz="0.0" iyy="9.509800000000002e-05" iyz="0.0" izz="0.00015021200000000002" />
        </inertial>
        <visual>
            <origin rpy="0 3.141592653589793 0" xyz="0 0 0" />
            <geometry>
                <mesh filename="package://robot_description/meshes/wheel_1.stl" scale="0.001 0.001 0.001" />
            </geometry>
            <material name="silver" />
        </visual>
        <collision>
            <origin rpy="0 1.5707963267948966 0" xyz="0 0 0" />
            <geometry>
                <cylinder length="0.042" radius="0.047" />
            </geometry>
        </collision>
    </link>
    <gazebo reference="front_right_wheel_link">
        <material>Gazebo/Green</material>
        <kp>1000000000000000000000000000.0</kp>
        <kd>1000000000000000000000000000.0</kd>
        <mu1 value="1000.0" />
        <mu2 value="100.0" />
    </gazebo>
    <joint name="front_right_wheel_joint" type="continuous">
        <origin rpy="0 0 0" xyz="0.09 0.145 -0.121" />
        <parent link="chassis_link" />
        <child link="front_right_wheel_link" />
        <axis xyz="1.0 0.0 0.0" />
    </joint>
    <link name="rear_left_wheel_link">
        <inertial>
            <origin rpy="0 1.5707963267948966 0" xyz="0 0 0" />
            <mass value="0.136" />
            <inertia ixx="9.509800000000002e-05" ixy="0.0" ixz="0.0" iyy="9.509800000000002e-05" iyz="0.0" izz="0.00015021200000000002" />
        </inertial>
        <visual>
            <origin rpy="0 0 0" xyz="0 0 0" />
            <geometry>
                <mesh filename="package://robot_description/meshes/wheel_1.stl" scale="0.001 0.001 0.001" />
            </geometry>
            <material name="silver" />
        </visual>
        <collision>
            <origin rpy="0 1.5707963267948966 0" xyz="0 0 0" />
            <geometry>
                <cylinder length="0.042" radius="0.047" />
            </geometry>
        </collision>
    </link>
    <gazebo reference="rear_left_wheel_link">
        <material>Gazebo/Green</material>
        <kp>1000000000000000000000000000.0</kp>
        <kd>1000000000000000000000000000.0</kd>
        <mu1 value="1000.0" />
        <mu2 value="100.0" />
    </gazebo>
    <joint name="rear_left_wheel_joint" type="continuous">
        <origin rpy="0 0 0" xyz="-0.09 -0.145 -0.121" />
        <parent link="chassis_link" />
        <child link="rear_left_wheel_link" />
        <axis xyz="1.0 0.0 0.0" />
    </joint>
    <link name="front_left_wheel_link">
        <inertial>
            <origin rpy="0 1.5707963267948966 0" xyz="0 0 0" />
            <mass value="0.136" />
            <inertia ixx="9.509800000000002e-05" ixy="0.0" ixz="0.0" iyy="9.509800000000002e-05" iyz="0.0" izz="0.00015021200000000002" />
        </inertial>
        <visual>
            <origin rpy="0 1.5707963267948966 0" xyz="0 0 0" />
            <geometry>
                <mesh filename="package://robot_description/meshes/wheel_2.stl" scale="0.001 0.001 0.001" />
            </geometry>
            <material name="silver" />
        </visual>
        <collision>
            <origin rpy="0 1.5707963267948966 0" xyz="0 0 0" />
            <geometry>
                <cylinder length="0.042" radius="0.047" />
            </geometry>
        </collision>
    </link>
    <gazebo reference="front_left_wheel_link">
        <material>Gazebo/Green</material>
        <kp>1000000000000000000000000000.0</kp>
        <kd>1000000000000000000000000000.0</kd>
        <mu1 value="1000.0" />
        <mu2 value="100.0" />
    </gazebo>
    <joint name="front_left_wheel_joint" type="continuous">
        <origin rpy="0 0 0" xyz="-0.09 0.145 -0.121" />
        <parent link="chassis_link" />
        <child link="front_left_wheel_link" />
        <axis xyz="1.0 0.0 0.0" />
    </joint>
    <link name="rear_right_wheel_link">
        <inertial>
            <origin rpy="0 1.5707963267948966 0" xyz="0 0 0" />
            <mass value="0.136" />
            <inertia ixx="9.509800000000002e-05" ixy="0.0" ixz="0.0" iyy="9.509800000000002e-05" iyz="0.0" izz="0.00015021200000000002" />
        </inertial>
        <visual>
            <origin rpy="0 -1.5707963267948966 0" xyz="0 0 0" />
            <geometry>
                <mesh filename="package://robot_description/meshes/wheel_2.stl" scale="0.001 0.001 0.001" />
            </geometry>
            <material name="silver" />
        </visual>
        <collision>
            <origin rpy="0 1.5707963267948966 0" xyz="0 0 0" />
            <geometry>
                <cylinder length="0.042" radius="0.047" />
            </geometry>
        </collision>
    </link>
    <gazebo reference="rear_right_wheel_link">
        <material>Gazebo/Green</material>
        <kp>1000000000000000000000000000.0</kp>
        <kd>1000000000000000000000000000.0</kd>
        <mu1 value="1000.0" />
        <mu2 value="100.0" />
    </gazebo>
    <joint name="rear_right_wheel_joint" type="continuous">
        <origin rpy="0 0 0" xyz="0.09 -0.145 -0.121" />
        <parent link="chassis_link" />
        <child link="rear_right_wheel_link" />
        <axis xyz="1.0 0.0 0.0" />
    </joint>
</robot>